<?xml version="1.0"?>
<robot name="collab_mobile_base" xmlns:xacro="http://www.ros.org/wiki/xacro">
  <xacro:property name="base_length" value="0.56"/>
  <xacro:property name="base_width" value="0.38"/>
  <xacro:property name="base_height" value="0.16"/>
  <xacro:property name="wheel_radius" value="0.06"/>
  <xacro:property name="wheel_width" value="0.045"/>
  <xacro:property name="wheel_y" value="0.215"/>
  <xacro:property name="wheel_x" value="0.0"/>

  <link name="base_footprint"/>

  <joint name="base_footprint_joint" type="fixed">
    <parent link="base_footprint"/>
    <child link="base_link"/>
    <origin xyz="0 0 0.11" rpy="0 0 0"/>
  </joint>

  <link name="base_link">
    <inertial>
      <origin xyz="0 0 0"/>
      <mass value="12.0"/>
      <inertia ixx="0.18" ixy="0.0" ixz="0.0" iyy="0.34" iyz="0.0" izz="0.42"/>
    </inertial>
    <visual>
      <origin xyz="0 0 0"/>
      <geometry>
        <box size="${base_length} ${base_width} ${base_height}"/>
      </geometry>
      <material name="collab_blue">
        <color rgba="0.1 0.34 0.72 1.0"/>
      </material>
    </visual>
    <collision>
      <origin xyz="0 0 0"/>
      <geometry>
        <box size="${base_length} ${base_width} ${base_height}"/>
      </geometry>
    </collision>
  </link>

  <xacro:macro name="wheel" params="name y">
    <link name="${name}_wheel_link">
      <inertial>
        <origin xyz="0 0 0"/>
        <mass value="0.7"/>
        <inertia ixx="0.0016" ixy="0.0" ixz="0.0" iyy="0.0016" iyz="0.0" izz="0.0024"/>
      </inertial>
      <visual>
        <origin xyz="0 0 0" rpy="1.5708 0 0"/>
        <geometry>
          <cylinder radius="${wheel_radius}" length="${wheel_width}"/>
        </geometry>
        <material name="wheel_dark">
          <color rgba="0.03 0.03 0.035 1.0"/>
        </material>
      </visual>
      <collision>
        <origin xyz="0 0 0" rpy="1.5708 0 0"/>
        <geometry>
          <cylinder radius="${wheel_radius}" length="${wheel_width}"/>
        </geometry>
      </collision>
    </link>
    <joint name="${name}_wheel_joint" type="continuous">
      <parent link="base_link"/>
      <child link="${name}_wheel_link"/>
      <origin xyz="${wheel_x} ${y} -0.06" rpy="0 0 0"/>
      <axis xyz="0 1 0"/>
    </joint>
  </xacro:macro>

  <xacro:wheel name="left" y="${wheel_y}"/>
  <xacro:wheel name="right" y="${-wheel_y}"/>

  <link name="front_caster_link">
    <visual>
      <origin xyz="0 0 0"/>
      <geometry>
        <sphere radius="0.035"/>
      </geometry>
      <material name="caster_gray">
        <color rgba="0.45 0.45 0.48 1.0"/>
      </material>
    </visual>
    <collision>
      <origin xyz="0 0 0"/>
      <geometry>
        <sphere radius="0.035"/>
      </geometry>
    </collision>
  </link>
  <joint name="front_caster_joint" type="fixed">
    <parent link="base_link"/>
    <child link="front_caster_link"/>
    <origin xyz="0.22 0 -0.07" rpy="0 0 0"/>
  </joint>

  <link name="lidar_link">
    <visual>
      <origin xyz="0 0 0"/>
      <geometry>
        <cylinder radius="0.055" length="0.045"/>
      </geometry>
      <material name="lidar_black">
        <color rgba="0.02 0.02 0.025 1.0"/>
      </material>
    </visual>
    <collision>
      <origin xyz="0 0 0"/>
      <geometry>
        <cylinder radius="0.055" length="0.045"/>
      </geometry>
    </collision>
  </link>
  <joint name="lidar_joint" type="fixed">
    <parent link="base_link"/>
    <child link="lidar_link"/>
    <origin xyz="0.18 0 0.12" rpy="0 0 0"/>
  </joint>

  <link name="camera_link">
    <visual>
      <origin xyz="0 0 0"/>
      <geometry>
        <box size="0.055 0.09 0.045"/>
      </geometry>
      <material name="camera_green">
        <color rgba="0.05 0.42 0.30 1.0"/>
      </material>
    </visual>
    <collision>
      <origin xyz="0 0 0"/>
      <geometry>
        <box size="0.055 0.09 0.045"/>
      </geometry>
    </collision>
  </link>
  <joint name="camera_joint" type="fixed">
    <parent link="base_link"/>
    <child link="camera_link"/>
    <origin xyz="0.30 0 0.08" rpy="0 0 0"/>
  </joint>

  <link name="imu_link"/>
  <joint name="imu_joint" type="fixed">
    <parent link="base_link"/>
    <child link="imu_link"/>
    <origin xyz="0 0 0.04" rpy="0 0 0"/>
  </joint>

  <gazebo reference="base_link">
    <material>Gazebo/Blue</material>
  </gazebo>
  <gazebo reference="left_wheel_link">
    <material>Gazebo/Black</material>
  </gazebo>
  <gazebo reference="right_wheel_link">
    <material>Gazebo/Black</material>
  </gazebo>

  <gazebo>
    <plugin name="diff_drive" filename="libgazebo_ros_diff_drive.so">
      <ros>
        <namespace>/</namespace>
        <remapping>cmd_vel:=cmd_vel</remapping>
        <remapping>odom:=odom</remapping>
      </ros>
      <update_rate>50</update_rate>
      <left_joint>left_wheel_joint</left_joint>
      <right_joint>right_wheel_joint</right_joint>
      <wheel_separation>0.43</wheel_separation>
      <wheel_diameter>0.12</wheel_diameter>
      <max_wheel_torque>20.0</max_wheel_torque>
      <max_wheel_acceleration>1.5</max_wheel_acceleration>
      <publish_odom>true</publish_odom>
      <publish_odom_tf>true</publish_odom_tf>
      <publish_wheel_tf>true</publish_wheel_tf>
      <odometry_frame>odom</odometry_frame>
      <robot_base_frame>base_footprint</robot_base_frame>
    </plugin>
  </gazebo>

  <gazebo reference="lidar_link">
    <sensor name="front_lidar" type="ray">
      <pose>0 0 0 0 0 0</pose>
      <always_on>true</always_on>
      <visualize>true</visualize>
      <update_rate>10</update_rate>
      <ray>
        <scan>
          <horizontal>
            <samples>360</samples>
            <resolution>1</resolution>
            <min_angle>-3.14159</min_angle>
            <max_angle>3.14159</max_angle>
          </horizontal>
        </scan>
        <range>
          <min>0.08</min>
          <max>8.0</max>
          <resolution>0.01</resolution>
        </range>
      </ray>
      <plugin name="gazebo_ros_lidar" filename="libgazebo_ros_ray_sensor.so">
        <ros>
          <namespace>/</namespace>
          <remapping>~/out:=scan</remapping>
        </ros>
        <output_type>sensor_msgs/LaserScan</output_type>
        <frame_name>lidar_link</frame_name>
      </plugin>
    </sensor>
  </gazebo>

  <gazebo reference="camera_link">
    <sensor name="front_rgb_camera" type="camera">
      <always_on>true</always_on>
      <visualize>true</visualize>
      <update_rate>15</update_rate>
      <camera>
        <horizontal_fov>1.047</horizontal_fov>
        <image>
          <width>640</width>
          <height>480</height>
          <format>R8G8B8</format>
        </image>
        <clip>
          <near>0.05</near>
          <far>12.0</far>
        </clip>
      </camera>
      <plugin name="front_camera_controller" filename="libgazebo_ros_camera.so">
        <ros>
          <namespace>/</namespace>
        </ros>
        <camera_name>camera/color</camera_name>
        <frame_name>camera_link</frame_name>
      </plugin>
    </sensor>
  </gazebo>

  <gazebo reference="imu_link">
    <sensor name="base_imu" type="imu">
      <always_on>true</always_on>
      <update_rate>100</update_rate>
      <plugin name="gazebo_ros_imu" filename="libgazebo_ros_imu_sensor.so">
        <ros>
          <namespace>/</namespace>
          <remapping>~/out:=imu/data</remapping>
        </ros>
        <frame_name>imu_link</frame_name>
      </plugin>
    </sensor>
  </gazebo>
</robot>
